Workbook
Name fmsS4: #REF!
Name fmsS2: #REF!
Name fmsS0: #REF!
Name fmsS1: #REF!
Name fmsS3: #REF!
Name misadS: 'MIS Archived Data'!$F:$J

Sheet CB
A1: Timestamp | B1: Your Name | C1: Client Name | D1: Sample of corrected format / photo of issue 1 | E1: Filter parameter (eg. semester, course, college, user, etc.) | F1: Type of issues | G1: Remarks | H1: Product name | I1: Report name | J1: I cofirm that I am clear with what is desired. | K1: Sample of corrected format / photo of issue 2 | L1: Email address | M1: Date
A2: 46083.579 | B2: Satish Kumar | C2: SMKV Bastar | D2: https://drive.google.com/open?id=19u430GOlyn0rSoq9ahjVQpRbpRXgsYJR | E2: as per the previous | F2: Other changes | G2: For the internal marks report, the download is showing blank data for every college. Kindly check and update. | H2: Smart-Exam | I2: marks entry report | J2: Yes | L2: satishkumar@learningspiral.co.in
A3: 46083.614 | B3: Khaleshwar | C3: KSU | D3: https://drive.google.com/open?id=1x4edvsdekkUBgTfjVm6qG_KDX-E6l2g5 | E3: admin | F3: Other changes | G3: ad | H3: Smart-Exam | I3: overalll pass report | J3: Yes | L3: khaleshwar@learningspiral.co.in
A4: 46083.615 | B4: khaleshwar | C4: singhaia university | D4: https://drive.google.com/open?id=1NOx1iLZmGhc7tYXwI9Y7kiH3Q8qUV4ns | E4: admin | F4: Other changes | G4: ad | H4: Smart-Exam | I4: cbcs tr report | J4: Yes | L4: khaleshwar@learningspiral.co.in
A5: 46084.634 | B5: Khaleshwar | C5: Singhania university | D5: https://drive.google.com/open?id=1YS3OdsLOL5lx_oG2WYzClsTQbBoq8L9f | E5: Admin | F5: Other changes | G5: Ad | H5: Smart-Exam | I5: Marksheet | J5: Yes | L5: khaleshwar@learningspiral.co.in
A6: 46084.659 | B6: Khaleshwar | C6: KSU | D6: https://drive.google.com/open?id=1tKfvhFOwLb02atunVIXX3DgDAYpXE3hE | E6: ADMIT | F6: Other changes | G6: ad | H6: Smart-Exam | I6: FINEL RESULT | J6: Yes | L6: khaleshwar@learningspiral.co.in
A7: 46086.442 | B7: chintu singh | C7: igu | D7: https://drive.google.com/open?id=1OD1An2IaORabIwBY4HzmndtIVbG7Yj7M | E7: Pls do the needful as per format for the session 2024-25 | F7: Change in logic, Change in design | G7: Pls do the needful as per format for the session 2024-25 | H7: Smart-Exam | I7: Pls do the needful as per format for the session 2024-25 | J7: Yes | L7: chintusingh@learningspiral.co.in
A8: 46086.688 | B8: AMIT YADU | C8: HYU, DURG | D8: https://drive.google.com/open?id=1r4zvF6Y3tMtUvatGlNYuK4boFFwhhAtl | E8: COURSE/SEMESTER | F8: Other changes | G8: DISTRICT WISE REPORT WAS NOT SHOWING | H8: Smart-Exam | I8: ENROLLMENT/REGISTRAION REPORT NEP | J8: Yes | L8: amityadu.gniit@gmail.com
A9: 46086.69 | B9: AMIT YADU | C9: HYU, DURG | D9: https://drive.google.com/open?id=14KDAIDpklWHuU6oGIDLbvDVRFrP40FLt | E9: SEM/COURSE | F9: Other changes | G9: TR IS NOT DOWNLOADING, PLZ SEND TR THROUGH MAIL (B.A. 1ST NEP) | H9: Smart-Exam | I9: TR REPORT | J9: Yes | L9: amityadu.gniit@gmail.com
A10: 46087.457 | B10: HARSHIT KUMAR | C10: IGU | D10: https://drive.google.com/open?id=1c8SyByaGMVOXS1UOmovp8hOBtGosM8I9 | E10: B.SC 2ND SEM REVAL MAY-2019 MARKSHEET BLANK | F10: Report not downloading | G10: DO THE CORRECTION AS PER ATTACHMENT | H10: Smart-Exam | I10: B.SC 2ND SEM REVAL MAY-2019 MARKSHEET BLANK | J10: Yes | K10: https://drive.google.com/open?id=1SsqLTD-dgURQgOkX6_iwGRf5AnZ2-MXC | L10: harshitkumar@learningspiral.co.in | U10: 0
A11: 46087.639 | B11: Ravikant Dewangan | C11: GAU | D11: https://drive.google.com/open?id=1aKyJqfwu32ugiHXZJRDPtCQIVoZLAoBv | E11: College Course | F11: Change in logic | G11: GAU Generate Attendance Sheet BAMS MARCH 2026 | H11: UCanAssess | I11: GAU Generate Attendance Sheet BAMS MARCH 2026 | J11: Yes | L11: tamannadewangan@learningspiral.co.in | U11: 0
A12: 46087.733 | B12: Rohit Singh | C12: SMKV | D12: https://drive.google.com/open?id=15Q0Dy3l85zME3ucBYLxN1KfeY5HjeRs1 | E12: Course Wise | F12: Change in design | G12: Please update the max marks as per discussion | H12: Smart-Exam | I12: Marks Entry Report | J12: Yes | L12: rohitsingh@learningspiral.co.in | U12: 0
A13: 46087.776 | B13: satish kumar | C13: smkv bastar | D13: https://drive.google.com/open?id=1m_Sul2U-W0TWqbD0-Ha_VKFeTXGhbnME | E13: as per the previous | F13: Other changes | G13: PLease update as per the discussion | H13: Smart-Exam | I13: exam time table repoort | J13: Yes | L13: satishkumar@learningspiral.co.in
A14: 46088.417 | B14: Ravikant Dewangan | C14: GAU | D14: https://drive.google.com/open?id=1RqYoKVO2NpX0W6xe-eXRPGH4mph-QX1r | E14: College & Course | F14: Change in logic | G14: Please generate the qr sticker in the previous format using the following table details: SELECT * FROM `gau_qrcode_generate`.`GAU_BAMS_march_2026_2nd` | H14: UCanAssess | I14: GAU Generate Attendance Sheet BAMS MARCH 2026 2nd LOT | J14: Yes | L14: tamannadewangan@learningspiral.co.in
A15: 46088.443 | B15: Rohit Singh | C15: SMKV | D15: https://drive.google.com/open?id=1V0vddiHHf4B6GfLRctFj1SAMRM3L74vN | E15: Course wise | F15: Change in design | G15: Please implement the changes as per discussion | H15: Smart-Exam | I15: Marks Sheet NEP | J15: Yes | L15: rohitsingh@learningspiral.co.in | U15: 0
A16: 46090.496 | B16: HARSHIT KUMAR | C16: IGU | D16: https://drive.google.com/open?id=1ptziOTMmZrCYpXt5GYuL_CSDh5BVDjfd | E16: M.S.W 3RD SEM TR NO OF PAGES | F16: Change in logic | G16: DO THE CORRECTION AS PER ATTACHMENT | H16: Smart-Exam | I16: M.S.W 3RD SEM TR NO OF PAGES | J16: Yes | K16: https://drive.google.com/open?id=1GhOv8mz381d4E3x_VLwIW5-p1t9lLxhc | L16: harshitkumar@learningspiral.co.in
A17: 46090.535 | B17: DEEPAK | C17: GNSU | D17: https://drive.google.com/open?id=1aWiOoYam2GpEK8YnwoRT49EBkzqy_8eU | E17: Gold Medel Certificate Final Year ( Annual Exam(PG)) PG MD - Anaesthesiology ( ANSTH)_SE15 | F17: Report not downloading | G17: KINDLY UPDATE THE FOURTH CONVOCATION | H17: Smart-Exam | I17: Gold Medel Certificate Gnsu | J17: Yes | L17: deepakkayal@learningspiral.co.in
A18: 46090.538 | B18: CHINTU SINGH | C18: IGU | D18: https://drive.google.com/open?id=18KNmdhuUgubw11G2MCGG5NxlwpOAV5Hd | E18: Regarding for M.ed 1st Sem regular admit card not show in roll number | F18: Report not downloading, Change in logic | G18: Regarding for M.ed 1st Sem regular admit card not show in roll number | H18: Smart-Exam | I18: ADMIT CARD | J18: Yes | L18: chintusingh@learningspiral.co.in
A19: 46090.54 | B19: Rajesh Gupta | C19: SKS International University | D19: https://drive.google.com/open?id=149MzaH_Hqy0Kc49qyQ8_hDoFh1wv57hv | E19: Course | F19: Other changes | G19: Please add the one Colome Year/Semester in this format | H19: Smart-Exam | I19: Enrolment/Exam form report | J19: Yes | L19: rajeshgupta@learningspiral.co.in
A20: 46090.576 | B20: KAMINI THAKUR | C20: SGBAU | D20: https://drive.google.com/open?id=1FHnmm9S1-hSTFSC3RsuK_6ONkwRAOhP5 | E20: MHRD TR | F20: Other changes | G20: TR RESULT HOSTING COLLEGEWISE ME TH MHRD KA FILE HONA | H20: Smart-Exam | I20: MULTIPLE REPORT | J20: Yes | L20: kamini19121985@gmail.com
A21: 46090.595 | B21: Tusar Chhatui | C21: MGU | D21: https://drive.google.com/open?id=1qNvVBFPAHJiUBsWL1nv9u2wF3iJvNQFW | E21: FINAL YEAR | F21: Change in logic | G21: Degree certificate correction | H21: Smart-Exam | I21: Degree certificate correction | J21: Yes | L21: tusarchhatui@learningspiral.co.in
A22: 46091.619 | B22: VIRENDRA KUMAR | C22: JMI | D22: https://drive.google.com/open?id=1NRuw0QT4OaOeoGGNGnwy8TTh4L345iwz | E22: provisional certificate | F22: Report not downloading | G22: signature change of off. controller | H22: Other | I22: provisional certificate | J22: Yes | K22: https://drive.google.com/open?id=1IT-DOUHCHA_GDyYxu14x9KVYkxUE8gUa | L22: virendrakumar@learningspiral.co.in
A23: 46091.623 | B23: Satish Kumar | C23: SMKV BASTAR | D23: https://drive.google.com/open?id=1UjbYREPBhDD-euOMZ8H138a_yA8ibX8w | E23: AS PER PREVIOUS | F23: Other changes | G23: PLEASE CHECK AND UPDATE AS THE ANNUAL SCHEMA | H23: Smart-Exam | I23: COLLEGE WISE TIME TABLE | J23: Yes | L23: satishkumar@learningspiral.co.in
A24: 46091.739 | B24: Rohit Singh | C24: SMKV | D24: https://drive.google.com/open?id=1VQdMSwGGC166jr8p8KNzfiC4JOIvWNjA | E24: Course Wise | F24: Change in design | G24: please do this | H24: Smart-Exam | I24: TR | J24: Yes | L24: rohitsingh@learningspiral.co.in
A25: 46091.813 | B25: Somen parui | C25: MZU | D25: https://drive.google.com/open?id=1tLUZlvAhMzVIoEjuJTxG8SW39MfeB9qN | E25: C000001,SE25,SM02,RE-APPEAR | F25: Change in design | G25: discuss with rup | H25: Smart-Exam | I25: 3152 | J25: Yes | L25: somenparui@learningspiral.co.in
A26: 46092.634 | B26: Ujjal das | C26: KSDSU | D26: https://drive.google.com/open?id=1tTlI48zeE6apcAG3ezeECElMTFARrLEE | E26: Upshastri 1st year | F26: Report not downloading | G26: TR not download | H26: Smart-Exam | I26: Upshastri TR not Download | J26: Yes | L26: ujjallspldas@gmail.com
A27: 46093.45 | B27: Khaleshwar | C27: SU | D27: https://drive.google.com/open?id=1JT8GKwXxYmlulArzMkxreZFRkxi8pkh7 | E27: college | F27: Other changes | G27: CBCS TR chnage the filter all and add collge wise | H27: Smart-Exam | I27: CBCS TR chnage the filter all and add collge wise | J27: Yes | L27: khaleshwar@learningspiral.co.in
A28: 46093.451 | B28: Khaleshwar | C28: SU | D28: https://drive.google.com/open?id=1OxKOYLqkTjPCGNz6ii-WWZ79g-N2yjad | E28: admin | F28: Other changes | G28: chnage the filter all and add collge wise | H28: Smart-Exam | I28: Marksheet chnage the filter all and add collge wise | J28: Yes | L28: khaleshwar@learningspiral.co.in
A29: 46093.451 | B29: Khaleshwar | C29: SU | D29: https://drive.google.com/open?id=1sM8I913yQcZCfTD53z338uYsIlAKxQ6g | E29: Adin | F29: Other changes | G29: chnage the filter all and add collge wise | H29: Smart-Exam | I29: Marksheet OLD chnage the filter all and add collge wise | J29: Yes | L29: khaleshwar@learningspiral.co.in
A30: 46093.452 | B30: Khaleshwar | C30: SU | D30: https://drive.google.com/open?id=1WfHtC_Q4_PAjysD5RQMDkZoVEvV1LE7_ | E30: admin | F30: Other changes | G30: chnage the filter all and add collge wise | H30: Smart-Exam | I30: Marksheet New chnage the filter all and add collge wise | J30: Yes | L30: khaleshwar@learningspiral.co.in
A31: 46093.52 | B31: Khaleshwar | C31: SU | D31: https://drive.google.com/open?id=1Y8MEkSA6nNUW13nJCphy4DUI0faqn9-p | E31: admin | F31: Other changes | G31: Plsae add the new collum in these exel BTACH | H31: Other | I31: Student enrooment report | J31: Yes | L31: khaleshwar@learningspiral.co.in
A32: 46093.554 | B32: chintu singh | C32: igu | D32: https://drive.google.com/open?id=1XzNltjJcfAhjTv0H4wP6VF3DasqQN7QS | E32: Award Sheet (Internal Assessment) Not Downloading M.Ed. 1st & 3rd Semester Session 2025- 26 | F32: Report not downloading | G32: Award Sheet (Internal Assessment) Not Downloading M.Ed. 1st & 3rd Semester Session 2025- 26 | H32: Smart-Exam | I32: Award Sheet Locked/Blank BMDCEM-201 - Baba Mohan Das College of Education, Motla Kalan, Rewari. PG MASTER OF EDUCATION ( M.ED) First Semester ( Sem - 1) Sessional Blank ENROLLMENTFORM_SE21 | J32: Yes | L32: chintusingh@learningspiral.co.in
A33: 46093.569 | B33: DEEPAK KAYAL | C33: GNSU | D33: https://drive.google.com/open?id=1dTVgOvo2Ge5U3Ia2kZCUTap2iAe7gSvv | E33: Final Certificate Sixth Semester ( 6th Sem) UG B.Sc. in Medical Radiology and Imaging Technology ( BMRIT)_SE13 | F33: Report not downloading | G33: PLEASE UPDATE DIVISION FROM PASSOUTDATA TABLE | H33: Smart-Exam | I33: CERTIFICATE | J33: Yes | K33: https://drive.google.com/open?id=1buZH2sqopta4MkdCydsD9j0qIxs8Luyr | L33: deepakkayal@learningspiral.co.in
A34: 46093.645 | B34: VIRENDRA KUMAR | C34: JMI | D34: https://drive.google.com/open?id=1ajtRYS6Jd9HRJbuxCkKy5GGlu7Ts3RTW | E34: OBTAINED MARKS IS GREATER THAN MAXIMUM MARKS. | F34: Other changes | G34: OBTAINED MARKS IS GREATER THAN MAXIMUM MARKS. | H34: UCanApply | I34: PROVISIONAL CERTIFICATE | J34: Yes | K34: https://drive.google.com/open?id=1D4G-gIvzOLKH3C1DnEpFatRM3Vnvkcx5 | L34: virendrakumar@learningspiral.co.in
A35: 46093.726 | B35: Somen parui | C35: MZU | D35: https://drive.google.com/open?id=1i7GU4WPlvNfFvimjcNgS-h0p9hHqXHdt | E35: previous all | F35: Change in logic, Change in design | G35: Discu s with rup | H35: Smart-Exam | I35: 3152 | J35: Yes | L35: somenparui@learningspiral.co.in
A36: 46093.735 | B36: AMIT KUMAR YADU | C36: HYU DURG | D36: https://drive.google.com/open?id=189EyqeomMlJ0q6j0VurZrBMYNmS_-KaA | E36: COLLEGE/COURSE | F36: Other changes | G36: LLB 6TH TR'S ATKT ATTEMPT NOT SHOWING | H36: Smart-Exam | I36: TR REPORT | J36: Yes | K36: https://drive.google.com/open?id=1cL0Qv7EhJd7V1zoBXG0DsxUlzQqBaL9x | L36: amityadu.gniit@gmail.com
A37: 46094.446 | B37: Rohit Singh | C37: SMKV | D37: https://drive.google.com/open?id=1veGKbscRXN4SgdfDK6foyrljxmze4Gp7 | E37: course | F37: Change in logic | G37: please do this | H37: Smart-Exam | I37: TR | J37: Yes | L37: rohitsingh@learningspiral.co.in
A38: 46094.489 | B38: DHIRAJ KUMAR | C38: CBLU | D38: https://drive.google.com/open?id=1-6jr6KEVCyMAp29mgEVAPRX-cd2KgDPy | E38: COURSE | F38: Change in logic | G38: RESULT DATA ADD 3 EXTRA FEILD | H38: Smart-Exam | I38: RESULT DATA | J38: Yes | L38: dhirajk@learningspiral.co.in
A39: 46094.522 | B39: Rajesh Gupta | C39: SKS International University | D39: https://drive.google.com/open?id=1_7vrffMJXSgF8zGgZfU1xFbWEjK2zroZ | E39: Course | F39: Other changes | G39: Please check the BAMS admit card Practical exam details not show | H39: Smart-Exam | I39: Admit card | J39: Yes | K39: https://drive.google.com/open?id=14koaHwmYqQa62dl1HdQ__hxOaLp_8u_o | L39: rajeshgupta@learningspiral.co.in
A40: 46094.524 | B40: Rajesh Gupta | C40: SKS International University | D40: https://drive.google.com/open?id=15j6QUN8x769dDTmA8mlMah13AW5zl2sy | E40: Course | F40: Other changes | G40: Please check the attached file I'm download the Attendance report some changes required. | H40: Smart-Exam | I40: Attendance Report | J40: Yes | K40: https://drive.google.com/open?id=1DcGLKjNOjdMFgsKpjjGUEwxImNpHqmMY | L40: rajeshgupta@learningspiral.co.in
...

Sheet Demo Sheet FMS_148
A1: =now() -> 46276.444 | B1: =19.5/24-9.5/24 -> 0.41666667 | C1: 9.5 | D1: 19.5 | G1: EMP3230 Shobha sahu | H1: FMS 148 Corrections/Bugs/ Update | M1: Discussion with Requester
A2: =TODAY() -> 46276 | B2: FMS 148 Corrections / Bugs / Update new logic in Existing report | M2: PC : EMP3200 Swati Soni | X2: Problem Solver L1 = Santosh Sir
M3: Step-2 | S3: Step-3 | X3: Step-4 | AC3: Step-5 | AH3: Step-6
A4: What | B4: Fill details about corrections and new logic in report | M4: Discussion with Requester | S4: Check api id from database and download jrmxl file | X4: Debuging the error (Jasper end as well as Query end) and discuss with RM about logic | AC4: Solution / Check data in database according to new logics | AH4: Upload file, cross check and inform to requester
A5: Who | B5: Co-ordinator | M5: EMP5009 Rup Kumar Mandal / EMP0042 HULESHWAR KUMAR SAHU / EMP0021 Tamanna Dewangan/EMP0237 Swarnendu Chakraborty | S5: EMP5009 Rup Kumar Mandal / EMP0042 HULESHWAR KUMAR SAHU / EMP0021 Tamanna Dewangan/EMP0237 Swarnendu Chakraborty | X5: EMP5009 Rup Kumar Mandal / EMP0042 HULESHWAR KUMAR SAHU / EMP0021 Tamanna Dewangan/EMP0237 Swarnendu Chakraborty | AC5: EMP5009 Rup Kumar Mandal / EMP0042 HULESHWAR KUMAR SAHU / EMP0021 Tamanna Dewangan/EMP0237 Swarnendu Chakraborty | AH5: EMP5009 Rup Kumar Mandal / EMP0042 HULESHWAR KUMAR SAHU / EMP0021 Tamanna Dewangan/EMP0237 Swarnendu Chakraborty
A6: How | B6: https://forms.gle/b3eJF6qHcDKEdhWu7 | M6: Call/Mail | S6: From database (jasper setting table based on report name) | X6: From Jrxml File and from Query on call | AC6: Logical part, From Jrxml File and from Query | AH6: In Jasper API, University panel, email, call | AN6: p=ArrayFormula(if($A$9:$A<>"",HYPERLINK("https://docs.google.com/forms/d/e/1FAIpQLScU7DKr6HbmoID_UwKfI13gEe3bspqg0MBmrgEwXFMuax8Tnw/viewform?usp=pp_url&entry.64613668="&$G$1&"&entry.947283785="&$H$1&"&entry.492682368="&$J$9:$J&"&entry.2053410063="&TEXT($B$9:$B,"yyyy-mm-dd")&"&entry.954149285="&$L$9:$L&"","Click Here"),""))
A7: When | B7: Anytime | M7: =4/24 -> 0.16666667 | S7: =0.1666666667/24 -> 0.0069444444 | X7: =2.5/24 -> 0.10416667 | AC7: 1 | AH7: =1/24 -> 0.041666667
A8: S. No. | B8: Timestamp | C8: Report name | D8: Client Name | E8: Sample of corrected format / photo of issue 1 | F8: Sample of corrected format / photo of issue 2 | G8: Filter paramater (eg. semester, course, college, user, etc.) | H8: Type of issues | I8: Product name | J8: Name of requester | K8: Date | L8: Remark (Description) | M8: Planned | N8: Actual | O8: Status | P8: Delay | Q8: Doer | R8: Conclusion Of Discussion | S8: Planned | T8: Actual | U8: Status | V8: Delay | W8: Doer | X8: Planned | Y8: Actual | Z8: Status | AA8: Delay | AB8: Doer | AC8: Planned | AD8: Actual | AE8: Status | AF8: Delay | AG8: Doer | AH8: Planned | AI8: Actual | AJ8: Status | AK8: Delay | AL8: Doer | AM8: Remarks | AN8: MOVE TO QC | AO8: TAT | AQ8: Step2 | AR8: Step3 | AS8: Step4 | AT8: Step5 | AU8: Step6 | AV8: 1
A9: 4960 | B9: {={CB!A2:A913,CB!I2:I913,CB!C2:C913,CB!D2:D913,CB!K2:K913,CB!E2:E913,CB!F2:F913,CB!H2:H913,CB!B2:B913,CB!M2:M913,CB!G2:G913}} -> 46083.579 | C9: marks entry report | D9: SMKV Bastar | E9: https://drive.google.com/open?id=19u430GOlyn0rSoq9ahjVQpRbpRXgsYJR | G9: as per the previous | H9: Other changes | I9: Smart-Exam | J9: Satish Kumar | L9: For the internal marks report, the download is showing blank data for every college. Kindly check and update. | M9: =if(B9,if(and(hour(B9+M$7)>9.5,(hour(B9+M$7)<19.5)),B9+M$7,_xlfn.workday.intl(int(B9),1,"0000001",Holidays!A:A)+hour(B9+M$7-$B$1)/24+minute(B9)/1440),"") -> 46083.745 | N9: 46083.632 | O9: Done | P9: =IF(B9<>0,(if(O9="Pending",if($A$2>M9,$A$2-M9,0),if(N9>M9,N9-M9,0))),"") -> 0 | Q9: EMP0042 HULESHWAR KUMAR SAHU | R9: Requirements Clear | S9: =if(M9,if(and(hour(M9+S$7)>9.5,(hour(M9+S$7)<19.5)),M9+S$7,_xlfn.workday.intl(int(M9),1,"0000001",Holidays!A:A)+hour(M9+S$7-$B$1)/24+minute(M9)/1440),"") -> 46083.752 | T9: 46083.633 | U9: Done | V9: =IF(B9<>0,(if(U9="Pending",if($A$2>S9,$A$2-S9,0),if(T9>S9,T9-S9,0))),"") -> 0 | W9: =IF(B9<>"",Q9,"") -> EMP0042 HULESHWAR KUMAR SAHU | X9: =if(S9,if(and(hour(S9+X$7)>9.5,(hour(S9+X$7)<19.5)),S9+X$7,_xlfn.workday.intl(int(S9),1,"0000001",Holidays!A:A)+hour(S9+X$7-$B$1)/24+minute(S9)/1440),"") -> 46084.419 | Y9: 46083.633 | Z9: Done | AA9: =IF(B9<>0,(if(Z9="Pending",if($AD$1>X9,$AD$1-X9,0),if(Y9>X9,Y9-X9,0))),"") -> 0 | AB9: =IF(B9<>"",W9,"") -> EMP0042 HULESHWAR KUMAR SAHU | AC9: =if(X9,_xlfn.WORKDAY.INTL(X9,AC$7,"0000001",Holidays!A:A)+hour(X9)/24+MINUTE(X9)/1440,"") -> 46086.419 | AD9: 46083.694 | AE9: Done | AF9: =IF(B9<>0,(if(AD9="Pending",if($A$2>AC9,$A$2-AC9,0),if(AD9>AC9,AD9-AC9,0))),"") -> 0 | AG9: =IF(B9<>"",AB9,"") -> EMP0042 HULESHWAR KUMAR SAHU | AH9: =if(AC9,if(and(hour(AC9+AH$7)>9.5,(hour(AC9+AH$7)<19.5)),AC9+AH$7,_xlfn.workday.intl(int(AC9),1,"0000001",Holidays!A:A)+hour(AC9+AH$7-$B$1)/24+minute(AC9)/1440),"") -> 46086.46 | AI9: 46083.694 | AJ9: Done | AK9: =IF(B9<>0,(if(AJ9="Pending",if($A$2>AH9,$A$2-AH9,0),if(AI9>AH9,AI9-AH9,0))),"") -> 0 | AL9: =IF(B9<>"",AG9,"") -> EMP0042 HULESHWAR KUMAR SAHU | AN9: {=if($A$9:$A913<>"",HYPERLINK("https://docs.google.com/forms/d/e/1FAIpQLScU7DKr6HbmoID_UwKfI13gEe3bspqg0MBmrgEwXFMuax8Tnw/viewform?usp=pp_url&entry.64613668="&$G$1&"&entry.947283785="&$H$1&"&entry.492682368="&$J$9:$J913&"&entry.2053410063="&TEXT($B$9:$B913,"yyyy-mm-dd")&"&entry.954149285="&$L$9:$L913&"","Click Here"),"")} -> Click Here
A10: =if($B10<>"",A9+1,"") -> 4961 | B10: 46083.614 | C10: overalll pass report | D10: KSU | E10: https://drive.google.com/open?id=1x4edvsdekkUBgTfjVm6qG_KDX-E6l2g5 | G10: admin | H10: Other changes | I10: Smart-Exam | J10: Khaleshwar | L10: ad | M10: =if(B10,if(and(hour(B10+M$7)>9.5,(hour(B10+M$7)<19.5)),B10+M$7,_xlfn.workday.intl(int(B10),1,"0000001",Holidays!A:A)+hour(B10+M$7-$B$1)/24+minute(B10)/1440),"") -> 46083.78 | N10: 46083.632 | O10: 490 | P10: =IF(B10<>0,(if(O10="Pending",if($A$2>M10,$A$2-M10,0),if(N10>M10,N10-M10,0))),"") -> 0 | Q10: EMP0042 HULESHWAR KUMAR SAHU | R10: Requirements Clear | S10: =if(M10,if(and(hour(M10+S$7)>9.5,(hour(M10+S$7)<19.5)),M10+S$7,_xlfn.workday.intl(int(M10),1,"0000001",Holidays!A:A)+hour(M10+S$7-$B$1)/24+minute(M10)/1440),"") -> 46083.787 | T10: 46083.633 | U10: 490 | V10: =IF(B10<>0,(if(U10="Pending",if($A$2>S10,$A$2-S10,0),if(T10>S10,T10-S10,0))),"") -> 0 | W10: =IF(B10<>"",Q10,"") -> EMP0042 HULESHWAR KUMAR SAHU | X10: =if(S10,if(and(hour(S10+X$7)>9.5,(hour(S10+X$7)<19.5)),S10+X$7,_xlfn.workday.intl(int(S10),1,"0000001",Holidays!A:A)+hour(S10+X$7-$B$1)/24+minute(S10)/1440),"") -> 46084.495 | Y10: 46083.633 | Z10: 495 | AA10: =IF(B10<>0,(if(Z10="Pending",if($AD$1>X10,$AD$1-X10,0),if(Y10>X10,Y10-X10,0))),"") -> 0 | AB10: =IF(B10<>"",W10,"") -> EMP0042 HULESHWAR KUMAR SAHU | AC10: =if(X10,_xlfn.WORKDAY.INTL(X10,AC$7,"0000001",Holidays!A:A)+hour(X10)/24+MINUTE(X10)/1440,"") -> 46086.495 | AD10: 46084.744 | AE10: Done | AF10: =IF(B10<>0,(if(AD10="Pending",if($A$2>AC10,$A$2-AC10,0),if(AD10>AC10,AD10-AC10,0))),"") -> 0 | AG10: =IF(B10<>"",AB10,"") -> EMP0042 HULESHWAR KUMAR SAHU | AH10: =if(AC10,if(and(hour(AC10+AH$7)>9.5,(hour(AC10+AH$7)<19.5)),AC10+AH$7,_xlfn.workday.intl(int(AC10),1,"0000001",Holidays!A:A)+hour(AC10+AH$7-$B$1)/24+minute(AC10)/1440),"") -> 46086.537 | AI10: 46084.744 | AJ10: 491 | AK10: =IF(B10<>0,(if(AJ10="Pending",if($A$2>AH10,$A$2-AH10,0),if(AI10>AH10,AI10-AH10,0))),"") -> 0 | AL10: =IF(B10<>"",AG10,"") -> EMP0042 HULESHWAR KUMAR SAHU | AN10: Click Here
A11: =if($B11<>"",A10+1,"") -> 4962 | B11: 46083.615 | C11: cbcs tr report | D11: singhaia university | E11: https://drive.google.com/open?id=1NOx1iLZmGhc7tYXwI9Y7kiH3Q8qUV4ns | G11: admin | H11: Other changes | I11: Smart-Exam | J11: khaleshwar | L11: ad | M11: =if(B11,if(and(hour(B11+M$7)>9.5,(hour(B11+M$7)<19.5)),B11+M$7,_xlfn.workday.intl(int(B11),1,"0000001",Holidays!A:A)+hour(B11+M$7-$B$1)/24+minute(B11)/1440),"") -> 46083.781 | N11: 46083.632 | O11: 490 | P11: =IF(B11<>0,(if(O11="Pending",if($A$2>M11,$A$2-M11,0),if(N11>M11,N11-M11,0))),"") -> 0 | Q11: EMP0237 Swarnendu Chakraborty | R11: Requirements Clear | S11: =if(M11,if(and(hour(M11+S$7)>9.5,(hour(M11+S$7)<19.5)),M11+S$7,_xlfn.workday.intl(int(M11),1,"0000001",Holidays!A:A)+hour(M11+S$7-$B$1)/24+minute(M11)/1440),"") -> 46083.788 | T11: 46083.632 | U11: 482 | V11: =IF(B11<>0,(if(U11="Pending",if($A$2>S11,$A$2-S11,0),if(T11>S11,T11-S11,0))),"") -> 0 | W11: =IF(B11<>"",Q11,"") -> EMP0237 Swarnendu Chakraborty | X11: =if(S11,if(and(hour(S11+X$7)>9.5,(hour(S11+X$7)<19.5)),S11+X$7,_xlfn.workday.intl(int(S11),1,"0000001",Holidays!A:A)+hour(S11+X$7-$B$1)/24+minute(S11)/1440),"") -> 46084.497 | Y11: 46083.633 | Z11: 493 | AA11: =IF(B11<>0,(if(Z11="Pending",if($AD$1>X11,$AD$1-X11,0),if(Y11>X11,Y11-X11,0))),"") -> 0 | AB11: =IF(B11<>"",W11,"") -> EMP0237 Swarnendu Chakraborty | AC11: =if(X11,_xlfn.WORKDAY.INTL(X11,AC$7,"0000001",Holidays!A:A)+hour(X11)/24+MINUTE(X11)/1440,"") -> 46086.497 | AD11: 46084.638 | AE11: Done | AF11: =IF(B11<>0,(if(AD11="Pending",if($A$2>AC11,$A$2-AC11,0),if(AD11>AC11,AD11-AC11,0))),"") -> 0 | AG11: =IF(B11<>"",AB11,"") -> EMP0237 Swarnendu Chakraborty | AH11: =if(AC11,if(and(hour(AC11+AH$7)>9.5,(hour(AC11+AH$7)<19.5)),AC11+AH$7,_xlfn.workday.intl(int(AC11),1,"0000001",Holidays!A:A)+hour(AC11+AH$7-$B$1)/24+minute(AC11)/1440),"") -> 46086.538 | AI11: 46084.638 | AJ11: 491 | AK11: =IF(B11<>0,(if(AJ11="Pending",if($A$2>AH11,$A$2-AH11,0),if(AI11>AH11,AI11-AH11,0))),"") -> 0 | AL11: =IF(B11<>"",AG11,"") -> EMP0237 Swarnendu Chakraborty | AN11: Click Here
A12: =if($B12<>"",A11+1,"") -> 4963 | B12: 46084.634 | C12: Marksheet | D12: Singhania university | E12: https://drive.google.com/open?id=1YS3OdsLOL5lx_oG2WYzClsTQbBoq8L9f | G12: Admin | H12: Other changes | I12: Smart-Exam | J12: Khaleshwar | L12: Ad | M12: =if(B12,if(and(hour(B12+M$7)>9.5,(hour(B12+M$7)<19.5)),B12+M$7,_xlfn.workday.intl(int(B12),1,"0000001",Holidays!A:A)+hour(B12+M$7-$B$1)/24+minute(B12)/1440),"") -> 46084.801 | N12: 46084.639 | O12: 0 | P12: =IF(B12<>0,(if(O12="Pending",if($A$2>M12,$A$2-M12,0),if(N12>M12,N12-M12,0))),"") -> 0 | Q12: EMP0237 Swarnendu Chakraborty | R12: Requirements Clear | S12: =if(M12,if(and(hour(M12+S$7)>9.5,(hour(M12+S$7)<19.5)),M12+S$7,_xlfn.workday.intl(int(M12),1,"0000001",Holidays!A:A)+hour(M12+S$7-$B$1)/24+minute(M12)/1440),"") -> 46084.808 | T12: 46084.639 | U12: 8 | V12: =IF(B12<>0,(if(U12="Pending",if($A$2>S12,$A$2-S12,0),if(T12>S12,T12-S12,0))),"") -> 0 | W12: =IF(B12<>"",Q12,"") -> EMP0237 Swarnendu Chakraborty | X12: =if(S12,if(and(hour(S12+X$7)>9.5,(hour(S12+X$7)<19.5)),S12+X$7,_xlfn.workday.intl(int(S12),1,"0000001",Holidays!A:A)+hour(S12+X$7-$B$1)/24+minute(S12)/1440),"") -> 46086.474 | Y12: 46084.639 | Z12: 2 | AA12: =IF(B12<>0,(if(Z12="Pending",if($AD$1>X12,$AD$1-X12,0),if(Y12>X12,Y12-X12,0))),"") -> 0 | AB12: =IF(B12<>"",W12,"") -> EMP0237 Swarnendu Chakraborty | AC12: =if(X12,_xlfn.WORKDAY.INTL(X12,AC$7,"0000001",Holidays!A:A)+hour(X12)/24+MINUTE(X12)/1440,"") -> 46087.474 | AD12: 46084.639 | AE12: Done | AF12: =IF(B12<>0,(if(AD12="Pending",if($A$2>AC12,$A$2-AC12,0),if(AD12>AC12,AD12-AC12,0))),"") -> 0 | AG12: =IF(B12<>"",AB12,"") -> EMP0237 Swarnendu Chakraborty | AH12: =if(AC12,if(and(hour(AC12+AH$7)>9.5,(hour(AC12+AH$7)<19.5)),AC12+AH$7,_xlfn.workday.intl(int(AC12),1,"0000001",Holidays!A:A)+hour(AC12+AH$7-$B$1)/24+minute(AC12)/1440),"") -> 46087.516 | AI12: 46084.639 | AJ12: 0 | AK12: =IF(B12<>0,(if(AJ12="Pending",if($A$2>AH12,$A$2-AH12,0),if(AI12>AH12,AI12-AH12,0))),"") -> 0 | AL12: =IF(B12<>"",AG12,"") -> EMP0237 Swarnendu Chakraborty | AN12: Click Here
A13: =if($B13<>"",A12+1,"") -> 4964 | B13: 46084.659 | C13: FINEL RESULT | D13: KSU | E13: https://drive.google.com/open?id=1tKfvhFOwLb02atunVIXX3DgDAYpXE3hE | G13: ADMIT | H13: Other changes | I13: Smart-Exam | J13: Khaleshwar | L13: ad | M13: =if(B13,if(and(hour(B13+M$7)>9.5,(hour(B13+M$7)<19.5)),B13+M$7,_xlfn.workday.intl(int(B13),1,"0000001",Holidays!A:A)+hour(B13+M$7-$B$1)/24+minute(B13)/1440),"") -> 46084.826 | N13: 46084.744 | O13: 46167.162 | P13: =IF(B13<>0,(if(O13="Pending",if($A$2>M13,$A$2-M13,0),if(N13>M13,N13-M13,0))),"") -> 0 | Q13: EMP0042 HULESHWAR KUMAR SAHU | R13: Requirements Clear | S13: =if(M13,if(and(hour(M13+S$7)>9.5,(hour(M13+S$7)<19.5)),M13+S$7,_xlfn.workday.intl(int(M13),1,"0000001",Holidays!A:A)+hour(M13+S$7-$B$1)/24+minute(M13)/1440),"") -> 46084.833 | T13: 46084.744 | U13: 46167.191 | V13: =IF(B13<>0,(if(U13="Pending",if($A$2>S13,$A$2-S13,0),if(T13>S13,T13-S13,0))),"") -> 0 | W13: =IF(B13<>"",Q13,"") -> EMP0042 HULESHWAR KUMAR SAHU | X13: =if(S13,if(and(hour(S13+X$7)>9.5,(hour(S13+X$7)<19.5)),S13+X$7,_xlfn.workday.intl(int(S13),1,"0000001",Holidays!A:A)+hour(S13+X$7-$B$1)/24+minute(S13)/1440),"") -> 46086.541 | Y13: 46084.744 | Z13: 46166.647 | AA13: =IF(B13<>0,(if(Z13="Pending",if($AD$1>X13,$AD$1-X13,0),if(Y13>X13,Y13-X13,0))),"") -> 0 | AB13: =IF(B13<>"",W13,"") -> EMP0042 HULESHWAR KUMAR SAHU | AC13: =if(X13,_xlfn.WORKDAY.INTL(X13,AC$7,"0000001",Holidays!A:A)+hour(X13)/24+MINUTE(X13)/1440,"") -> 46087.541 | AD13: 46084.745 | AE13: Done | AF13: =IF(B13<>0,(if(AD13="Pending",if($A$2>AC13,$A$2-AC13,0),if(AD13>AC13,AD13-AC13,0))),"") -> 0 | AG13: =IF(B13<>"",AB13,"") -> EMP0042 HULESHWAR KUMAR SAHU | AH13: =if(AC13,if(and(hour(AC13+AH$7)>9.5,(hour(AC13+AH$7)<19.5)),AC13+AH$7,_xlfn.workday.intl(int(AC13),1,"0000001",Holidays!A:A)+hour(AC13+AH$7-$B$1)/24+minute(AC13)/1440),"") -> 46087.583 | AI13: 46084.745 | AJ13: 46167.419 | AK13: =IF(B13<>0,(if(AJ13="Pending",if($A$2>AH13,$A$2-AH13,0),if(AI13>AH13,AI13-AH13,0))),"") -> 0 | AL13: =IF(B13<>"",AG13,"") -> EMP0042 HULESHWAR KUMAR SAHU | AN13: Click Here
A14: =if($B14<>"",A13+1,"") -> 4965 | B14: 46086.442 | C14: Pls do the needful as per format for the session 2024-25 | D14: igu | E14: https://drive.google.com/open?id=1OD1An2IaORabIwBY4HzmndtIVbG7Yj7M | G14: Pls do the needful as per format for the session 2024-25 | H14: Change in logic, Change in design | I14: Smart-Exam | J14: chintu singh | L14: Pls do the needful as per format for the session 2024-25 | M14: =if(B14,if(and(hour(B14+M$7)>9.5,(hour(B14+M$7)<19.5)),B14+M$7,_xlfn.workday.intl(int(B14),1,"0000001",Holidays!A:A)+hour(B14+M$7-$B$1)/24+minute(B14)/1440),"") -> 46086.608 | N14: 46086.493 | O14: 46166.821 | P14: =IF(B14<>0,(if(O14="Pending",if($A$2>M14,$A$2-M14,0),if(N14>M14,N14-M14,0))),"") -> 0 | Q14: EMP0021 Tamanna Dewangan | R14: Requirements Clear | S14: =if(M14,if(and(hour(M14+S$7)>9.5,(hour(M14+S$7)<19.5)),M14+S$7,_xlfn.workday.intl(int(M14),1,"0000001",Holidays!A:A)+hour(M14+S$7-$B$1)/24+minute(M14)/1440),"") -> 46086.615 | T14: 46086.493 | U14: 46166.829 | V14: =IF(B14<>0,(if(U14="Pending",if($A$2>S14,$A$2-S14,0),if(T14>S14,T14-S14,0))),"") -> 0 | W14: =IF(B14<>"",Q14,"") -> EMP0021 Tamanna Dewangan | X14: =if(S14,if(and(hour(S14+X$7)>9.5,(hour(S14+X$7)<19.5)),S14+X$7,_xlfn.workday.intl(int(S14),1,"0000001",Holidays!A:A)+hour(S14+X$7-$B$1)/24+minute(S14)/1440),"") -> 46086.719 | Y14: 46086.493 | Z14: 46166.076 | AA14: =IF(B14<>0,(if(Z14="Pending",if($AD$1>X14,$AD$1-X14,0),if(Y14>X14,Y14-X14,0))),"") -> 0 | AB14: =IF(B14<>"",W14,"") -> EMP0021 Tamanna Dewangan | AC14: =if(X14,_xlfn.WORKDAY.INTL(X14,AC$7,"0000001",Holidays!A:A)+hour(X14)/24+MINUTE(X14)/1440,"") -> 46087.719 | AD14: 46086.629 | AE14: Done | AF14: =IF(B14<>0,(if(AD14="Pending",if($A$2>AC14,$A$2-AC14,0),if(AD14>AC14,AD14-AC14,0))),"") -> 0 | AG14: =IF(B14<>"",AB14,"") -> EMP0021 Tamanna Dewangan | AH14: =if(AC14,if(and(hour(AC14+AH$7)>9.5,(hour(AC14+AH$7)<19.5)),AC14+AH$7,_xlfn.workday.intl(int(AC14),1,"0000001",Holidays!A:A)+hour(AC14+AH$7-$B$1)/24+minute(AC14)/1440),"") -> 46087.76 | AI14: 46087.409 | AJ14: 46166.285 | AK14: =IF(B14<>0,(if(AJ14="Pending",if($A$2>AH14,$A$2-AH14,0),if(AI14>AH14,AI14-AH14,0))),"") -> 0 | AL14: =IF(B14<>"",AG14,"") -> EMP0021 Tamanna Dewangan | AN14: Click Here
A15: =if($B15<>"",A14+1,"") -> 4966 | B15: 46086.688 | C15: ENROLLMENT/REGISTRAION REPORT NEP | D15: HYU, DURG | E15: https://drive.google.com/open?id=1r4zvF6Y3tMtUvatGlNYuK4boFFwhhAtl | G15: COURSE/SEMESTER | H15: Other changes | I15: Smart-Exam | J15: AMIT YADU | L15: DISTRICT WISE REPORT WAS NOT SHOWING | M15: =if(B15,if(and(hour(B15+M$7)>9.5,(hour(B15+M$7)<19.5)),B15+M$7,_xlfn.workday.intl(int(B15),1,"0000001",Holidays!A:A)+hour(B15+M$7-$B$1)/24+minute(B15)/1440),"") -> 46087.438 | N15: 46086.701 | O15: Done | P15: =IF(B15<>0,(if(O15="Pending",if($A$2>M15,$A$2-M15,0),if(N15>M15,N15-M15,0))),"") -> 0 | Q15: EMP5009 Rup Kumar Mandal | R15: Requirements Clear | S15: =if(M15,if(and(hour(M15+S$7)>9.5,(hour(M15+S$7)<19.5)),M15+S$7,_xlfn.workday.intl(int(M15),1,"0000001",Holidays!A:A)+hour(M15+S$7-$B$1)/24+minute(M15)/1440),"") -> 46087.445 | T15: 46086.701 | U15: Done | V15: =IF(B15<>0,(if(U15="Pending",if($A$2>S15,$A$2-S15,0),if(T15>S15,T15-S15,0))),"") -> 0 | W15: =IF(B15<>"",Q15,"") -> EMP5009 Rup Kumar Mandal | X15: =if(S15,if(and(hour(S15+X$7)>9.5,(hour(S15+X$7)<19.5)),S15+X$7,_xlfn.workday.intl(int(S15),1,"0000001",Holidays!A:A)+hour(S15+X$7-$B$1)/24+minute(S15)/1440),"") -> 46087.549 | Y15: 46086.712 | Z15: Done | AA15: =IF(B15<>0,(if(Z15="Pending",if($AD$1>X15,$AD$1-X15,0),if(Y15>X15,Y15-X15,0))),"") -> 0 | AB15: =IF(B15<>"",W15,"") -> EMP5009 Rup Kumar Mandal | AC15: =if(X15,_xlfn.WORKDAY.INTL(X15,AC$7,"0000001",Holidays!A:A)+hour(X15)/24+MINUTE(X15)/1440,"") -> 46088.549 | AD15: 46087.663 | AE15: Done | AF15: =IF(B15<>0,(if(AD15="Pending",if($A$2>AC15,$A$2-AC15,0),if(AD15>AC15,AD15-AC15,0))),"") -> 0 | AG15: =IF(B15<>"",AB15,"") -> EMP5009 Rup Kumar Mandal | AH15: =if(AC15,if(and(hour(AC15+AH$7)>9.5,(hour(AC15+AH$7)<19.5)),AC15+AH$7,_xlfn.workday.intl(int(AC15),1,"0000001",Holidays!A:A)+hour(AC15+AH$7-$B$1)/24+minute(AC15)/1440),"") -> 46088.591 | AI15: 46087.663 | AJ15: Done | AK15: =IF(B15<>0,(if(AJ15="Pending",if($A$2>AH15,$A$2-AH15,0),if(AI15>AH15,AI15-AH15,0))),"") -> 0 | AL15: =IF(B15<>"",AG15,"") -> EMP5009 Rup Kumar Mandal | AN15: Click Here
A16: =if($B16<>"",A15+1,"") -> 4967 | B16: 46086.69 | C16: TR REPORT | D16: HYU, DURG | E16: https://drive.google.com/open?id=14KDAIDpklWHuU6oGIDLbvDVRFrP40FLt | G16: SEM/COURSE | H16: Other changes | I16: Smart-Exam | J16: AMIT YADU | L16: TR IS NOT DOWNLOADING, PLZ SEND TR THROUGH MAIL (B.A. 1ST NEP) | M16: =if(B16,if(and(hour(B16+M$7)>9.5,(hour(B16+M$7)<19.5)),B16+M$7,_xlfn.workday.intl(int(B16),1,"0000001",Holidays!A:A)+hour(B16+M$7-$B$1)/24+minute(B16)/1440),"") -> 46087.44 | N16: 46086.701 | O16: Done | P16: =IF(B16<>0,(if(O16="Pending",if($A$2>M16,$A$2-M16,0),if(N16>M16,N16-M16,0))),"") -> 0 | Q16: EMP5009 Rup Kumar Mandal | R16: Requirements Clear | S16: =if(M16,if(and(hour(M16+S$7)>9.5,(hour(M16+S$7)<19.5)),M16+S$7,_xlfn.workday.intl(int(M16),1,"0000001",Holidays!A:A)+hour(M16+S$7-$B$1)/24+minute(M16)/1440),"") -> 46087.447 | T16: 46086.701 | U16: Done | V16: =IF(B16<>0,(if(U16="Pending",if($A$2>S16,$A$2-S16,0),if(T16>S16,T16-S16,0))),"") -> 0 | W16: =IF(B16<>"",Q16,"") -> EMP5009 Rup Kumar Mandal | X16: =if(S16,if(and(hour(S16+X$7)>9.5,(hour(S16+X$7)<19.5)),S16+X$7,_xlfn.workday.intl(int(S16),1,"0000001",Holidays!A:A)+hour(S16+X$7-$B$1)/24+minute(S16)/1440),"") -> 46087.551 | Y16: 46086.712 | Z16: Done | AA16: =IF(B16<>0,(if(Z16="Pending",if($AD$1>X16,$AD$1-X16,0),if(Y16>X16,Y16-X16,0))),"") -> 0 | AB16: =IF(B16<>"",W16,"") -> EMP5009 Rup Kumar Mandal | AC16: =if(X16,_xlfn.WORKDAY.INTL(X16,AC$7,"0000001",Holidays!A:A)+hour(X16)/24+MINUTE(X16)/1440,"") -> 46088.551 | AD16: 46087.663 | AE16: Done | AF16: =IF(B16<>0,(if(AD16="Pending",if($A$2>AC16,$A$2-AC16,0),if(AD16>AC16,AD16-AC16,0))),"") -> 0 | AG16: =IF(B16<>"",AB16,"") -> EMP5009 Rup Kumar Mandal | AH16: =if(AC16,if(and(hour(AC16+AH$7)>9.5,(hour(AC16+AH$7)<19.5)),AC16+AH$7,_xlfn.workday.intl(int(AC16),1,"0000001",Holidays!A:A)+hour(AC16+AH$7-$B$1)/24+minute(AC16)/1440),"") -> 46088.593 | AI16: 46087.663 | AJ16: Done | AK16: =IF(B16<>0,(if(AJ16="Pending",if($A$2>AH16,$A$2-AH16,0),if(AI16>AH16,AI16-AH16,0))),"") -> 0 | AL16: =IF(B16<>"",AG16,"") -> EMP5009 Rup Kumar Mandal | AN16: Click Here
A17: =if($B17<>"",A16+1,"") -> 4968 | B17: 46087.457 | C17: B.SC 2ND SEM REVAL MAY-2019 MARKSHEET BLANK | D17: IGU | E17: https://drive.google.com/open?id=1c8SyByaGMVOXS1UOmovp8hOBtGosM8I9 | F17: https://drive.google.com/open?id=1SsqLTD-dgURQgOkX6_iwGRf5AnZ2-MXC | G17: B.SC 2ND SEM REVAL MAY-2019 MARKSHEET BLANK | H17: Report not downloading | I17: Smart-Exam | J17: HARSHIT KUMAR | L17: DO THE CORRECTION AS PER ATTACHMENT | M17: =if(B17,if(and(hour(B17+M$7)>9.5,(hour(B17+M$7)<19.5)),B17+M$7,_xlfn.workday.intl(int(B17),1,"0000001",Holidays!A:A)+hour(B17+M$7-$B$1)/24+minute(B17)/1440),"") -> 46087.624 | N17: 46087.474 | O17: Done | P17: =IF(B17<>0,(if(O17="Pending",if($A$2>M17,$A$2-M17,0),if(N17>M17,N17-M17,0))),"") -> 0 | Q17: EMP0042 HULESHWAR KUMAR SAHU | R17: Requirements Clear | S17: =if(M17,if(and(hour(M17+S$7)>9.5,(hour(M17+S$7)<19.5)),M17+S$7,_xlfn.workday.intl(int(M17),1,"0000001",Holidays!A:A)+hour(M17+S$7-$B$1)/24+minute(M17)/1440),"") -> 46087.631 | T17: 46087.474 | U17: Done | V17: =IF(B17<>0,(if(U17="Pending",if($A$2>S17,$A$2-S17,0),if(T17>S17,T17-S17,0))),"") -> 0 | W17: =IF(B17<>"",Q17,"") -> EMP0042 HULESHWAR KUMAR SAHU | X17: =if(S17,if(and(hour(S17+X$7)>9.5,(hour(S17+X$7)<19.5)),S17+X$7,_xlfn.workday.intl(int(S17),1,"0000001",Holidays!A:A)+hour(S17+X$7-$B$1)/24+minute(S17)/1440),"") -> 46087.735 | Y17: 46087.474 | Z17: Done | AA17: =IF(B17<>0,(if(Z17="Pending",if($AD$1>X17,$AD$1-X17,0),if(Y17>X17,Y17-X17,0))),"") -> 0 | AB17: =IF(B17<>"",W17,"") -> EMP0042 HULESHWAR KUMAR SAHU | AC17: =if(X17,_xlfn.WORKDAY.INTL(X17,AC$7,"0000001",Holidays!A:A)+hour(X17)/24+MINUTE(X17)/1440,"") -> 46088.735 | AD17: 46087.496 | AE17: Done | AF17: =IF(B17<>0,(if(AD17="Pending",if($A$2>AC17,$A$2-AC17,0),if(AD17>AC17,AD17-AC17,0))),"") -> 0 | AG17: =IF(B17<>"",AB17,"") -> EMP0042 HULESHWAR KUMAR SAHU | AH17: =if(AC17,if(and(hour(AC17+AH$7)>9.5,(hour(AC17+AH$7)<19.5)),AC17+AH$7,_xlfn.workday.intl(int(AC17),1,"0000001",Holidays!A:A)+hour(AC17+AH$7-$B$1)/24+minute(AC17)/1440),"") -> 46088.776 | AI17: 46087.496 | AJ17: Done | AK17: =IF(B17<>0,(if(AJ17="Pending",if($A$2>AH17,$A$2-AH17,0),if(AI17>AH17,AI17-AH17,0))),"") -> 0 | AL17: =IF(B17<>"",AG17,"") -> EMP0042 HULESHWAR KUMAR SAHU | AN17: Click Here
A18: =if($B18<>"",A17+1,"") -> 4969 | B18: 46087.639 | C18: GAU Generate Attendance Sheet BAMS MARCH 2026 | D18: GAU | E18: https://drive.google.com/open?id=1aKyJqfwu32ugiHXZJRDPtCQIVoZLAoBv | G18: College Course | H18: Change in logic | I18: UCanAssess | J18: Ravikant Dewangan | L18: GAU Generate Attendance Sheet BAMS MARCH 2026 | M18: =if(B18,if(and(hour(B18+M$7)>9.5,(hour(B18+M$7)<19.5)),B18+M$7,_xlfn.workday.intl(int(B18),1,"0000001",Holidays!A:A)+hour(B18+M$7-$B$1)/24+minute(B18)/1440),"") -> 46087.806 | N18: 46087.64 | O18: Done | P18: =IF(B18<>0,(if(O18="Pending",if($A$2>M18,$A$2-M18,0),if(N18>M18,N18-M18,0))),"") -> 0 | Q18: EMP0021 Tamanna Dewangan | R18: Requirements Clear | S18: =if(M18,if(and(hour(M18+S$7)>9.5,(hour(M18+S$7)<19.5)),M18+S$7,_xlfn.workday.intl(int(M18),1,"0000001",Holidays!A:A)+hour(M18+S$7-$B$1)/24+minute(M18)/1440),"") -> 46087.813 | T18: 46087.641 | U18: Done | V18: =IF(B18<>0,(if(U18="Pending",if($A$2>S18,$A$2-S18,0),if(T18>S18,T18-S18,0))),"") -> 0 | W18: =IF(B18<>"",Q18,"") -> EMP0021 Tamanna Dewangan | X18: =if(S18,if(and(hour(S18+X$7)>9.5,(hour(S18+X$7)<19.5)),S18+X$7,_xlfn.workday.intl(int(S18),1,"0000001",Holidays!A:A)+hour(S18+X$7-$B$1)/24+minute(S18)/1440),"") -> 46088.521 | Y18: 46088.418 | Z18: Done | AA18: =IF(B18<>0,(if(Z18="Pending",if($AD$1>X18,$AD$1-X18,0),if(Y18>X18,Y18-X18,0))),"") -> 0 | AB18: =IF(B18<>"",W18,"") -> EMP0021 Tamanna Dewangan | AC18: =if(X18,_xlfn.WORKDAY.INTL(X18,AC$7,"0000001",Holidays!A:A)+hour(X18)/24+MINUTE(X18)/1440,"") -> 46090.521 | AD18: 46088.418 | AE18: Done | AF18: =IF(B18<>0,(if(AD18="Pending",if($A$2>AC18,$A$2-AC18,0),if(AD18>AC18,AD18-AC18,0))),"") -> 0 | AG18: =IF(B18<>"",AB18,"") -> EMP0021 Tamanna Dewangan | AH18: =if(AC18,if(and(hour(AC18+AH$7)>9.5,(hour(AC18+AH$7)<19.5)),AC18+AH$7,_xlfn.workday.intl(int(AC18),1,"0000001",Holidays!A:A)+hour(AC18+AH$7-$B$1)/24+minute(AC18)/1440),"") -> 46090.562 | AI18: 46088.418 | AJ18: Done | AK18: =IF(B18<>0,(if(AJ18="Pending",if($A$2>AH18,$A$2-AH18,0),if(AI18>AH18,AI18-AH18,0))),"") -> 0 | AL18: =IF(B18<>"",AG18,"") -> EMP0021 Tamanna Dewangan | AN18: Click Here
A19: =if($B19<>"",A18+1,"") -> 4970 | B19: 46087.733 | C19: Marks Entry Report | D19: SMKV | E19: https://drive.google.com/open?id=15Q0Dy3l85zME3ucBYLxN1KfeY5HjeRs1 | G19: Course Wise | H19: Change in design | I19: Smart-Exam | J19: Rohit Singh | L19: Please update the max marks as per discussion | M19: =if(B19,if(and(hour(B19+M$7)>9.5,(hour(B19+M$7)<19.5)),B19+M$7,_xlfn.workday.intl(int(B19),1,"0000001",Holidays!A:A)+hour(B19+M$7-$B$1)/24+minute(B19)/1440),"") -> 46088.483 | N19: 46087.736 | O19: Done | P19: =IF(B19<>0,(if(O19="Pending",if($A$2>M19,$A$2-M19,0),if(N19>M19,N19-M19,0))),"") -> 0 | Q19: EMP0042 HULESHWAR KUMAR SAHU | R19: Requirements Clear | S19: =if(M19,if(and(hour(M19+S$7)>9.5,(hour(M19+S$7)<19.5)),M19+S$7,_xlfn.workday.intl(int(M19),1,"0000001",Holidays!A:A)+hour(M19+S$7-$B$1)/24+minute(M19)/1440),"") -> 46088.49 | T19: 46087.736 | U19: Done | V19: =IF(B19<>0,(if(U19="Pending",if($A$2>S19,$A$2-S19,0),if(T19>S19,T19-S19,0))),"") -> 0 | W19: =IF(B19<>"",Q19,"") -> EMP0042 HULESHWAR KUMAR SAHU | X19: =if(S19,if(and(hour(S19+X$7)>9.5,(hour(S19+X$7)<19.5)),S19+X$7,_xlfn.workday.intl(int(S19),1,"0000001",Holidays!A:A)+hour(S19+X$7-$B$1)/24+minute(S19)/1440),"") -> 46088.594 | Y19: 46087.736 | Z19: Done | AA19: =IF(B19<>0,(if(Z19="Pending",if($AD$1>X19,$AD$1-X19,0),if(Y19>X19,Y19-X19,0))),"") -> 0 | AB19: =IF(B19<>"",W19,"") -> EMP0042 HULESHWAR KUMAR SAHU | AC19: =if(X19,_xlfn.WORKDAY.INTL(X19,AC$7,"0000001",Holidays!A:A)+hour(X19)/24+MINUTE(X19)/1440,"") -> 46090.594 | AD19: 46088.449 | AE19: Done | AF19: =IF(B19<>0,(if(AD19="Pending",if($A$2>AC19,$A$2-AC19,0),if(AD19>AC19,AD19-AC19,0))),"") -> 0 | AG19: =IF(B19<>"",AB19,"") -> EMP0042 HULESHWAR KUMAR SAHU | AH19: =if(AC19,if(and(hour(AC19+AH$7)>9.5,(hour(AC19+AH$7)<19.5)),AC19+AH$7,_xlfn.workday.intl(int(AC19),1,"0000001",Holidays!A:A)+hour(AC19+AH$7-$B$1)/24+minute(AC19)/1440),"") -> 46090.635 | AI19: 46088.449 | AJ19: Done | AK19: =IF(B19<>0,(if(AJ19="Pending",if($A$2>AH19,$A$2-AH19,0),if(AI19>AH19,AI19-AH19,0))),"") -> 0 | AL19: =IF(B19<>"",AG19,"") -> EMP0042 HULESHWAR KUMAR SAHU | AN19: Click Here
A20: =if($B20<>"",A19+1,"") -> 4971 | B20: 46087.776 | C20: exam time table repoort | D20: smkv bastar | E20: https://drive.google.com/open?id=1m_Sul2U-W0TWqbD0-Ha_VKFeTXGhbnME | G20: as per the previous | H20: Other changes | I20: Smart-Exam | J20: satish kumar | L20: PLease update as per the discussion | M20: =if(B20,if(and(hour(B20+M$7)>9.5,(hour(B20+M$7)<19.5)),B20+M$7,_xlfn.workday.intl(int(B20),1,"0000001",Holidays!A:A)+hour(B20+M$7-$B$1)/24+minute(B20)/1440),"") -> 46088.526 | N20: 46088.417 | O20: Done | P20: =IF(B20<>0,(if(O20="Pending",if($A$2>M20,$A$2-M20,0),if(N20>M20,N20-M20,0))),"") -> 0 | Q20: EMP0042 HULESHWAR KUMAR SAHU | R20: Requirements Clear | S20: =if(M20,if(and(hour(M20+S$7)>9.5,(hour(M20+S$7)<19.5)),M20+S$7,_xlfn.workday.intl(int(M20),1,"0000001",Holidays!A:A)+hour(M20+S$7-$B$1)/24+minute(M20)/1440),"") -> 46088.533 | T20: 46088.418 | U20: Done | V20: =IF(B20<>0,(if(U20="Pending",if($A$2>S20,$A$2-S20,0),if(T20>S20,T20-S20,0))),"") -> 0 | W20: =IF(B20<>"",Q20,"") -> EMP0042 HULESHWAR KUMAR SAHU | X20: =if(S20,if(and(hour(S20+X$7)>9.5,(hour(S20+X$7)<19.5)),S20+X$7,_xlfn.workday.intl(int(S20),1,"0000001",Holidays!A:A)+hour(S20+X$7-$B$1)/24+minute(S20)/1440),"") -> 46088.637 | Y20: 46088.418 | Z20: Done | AA20: =IF(B20<>0,(if(Z20="Pending",if($AD$1>X20,$AD$1-X20,0),if(Y20>X20,Y20-X20,0))),"") -> 0 | AB20: =IF(B20<>"",W20,"") -> EMP0042 HULESHWAR KUMAR SAHU | AC20: =if(X20,_xlfn.WORKDAY.INTL(X20,AC$7,"0000001",Holidays!A:A)+hour(X20)/24+MINUTE(X20)/1440,"") -> 46090.637 | AD20: 46088.449 | AE20: Done | AF20: =IF(B20<>0,(if(AD20="Pending",if($A$2>AC20,$A$2-AC20,0),if(AD20>AC20,AD20-AC20,0))),"") -> 0 | AG20: =IF(B20<>"",AB20,"") -> EMP0042 HULESHWAR KUMAR SAHU | AH20: =if(AC20,if(and(hour(AC20+AH$7)>9.5,(hour(AC20+AH$7)<19.5)),AC20+AH$7,_xlfn.workday.intl(int(AC20),1,"0000001",Holidays!A:A)+hour(AC20+AH$7-$B$1)/24+minute(AC20)/1440),"") -> 46090.678 | AI20: 46088.501 | AJ20: Done | AK20: =IF(B20<>0,(if(AJ20="Pending",if($A$2>AH20,$A$2-AH20,0),if(AI20>AH20,AI20-AH20,0))),"") -> 0 | AL20: =IF(B20<>"",AG20,"") -> EMP0042 HULESHWAR KUMAR SAHU | AN20: Click Here
A21: =if($B21<>"",A20+1,"") -> 4972 | B21: 46088.417 | C21: GAU Generate Attendance Sheet BAMS MARCH 2026 2nd LOT | D21: GAU | E21: https://drive.google.com/open?id=1RqYoKVO2NpX0W6xe-eXRPGH4mph-QX1r | G21: College & Course | H21: Change in logic | I21: UCanAssess | J21: Ravikant Dewangan | L21: Please generate the qr sticker in the previous format using the following table details: SELECT * FROM `gau_qrcode_generate`.`GAU_BAMS_march_2026_2nd` | M21: =if(B21,if(and(hour(B21+M$7)>9.5,(hour(B21+M$7)<19.5)),B21+M$7,_xlfn.workday.intl(int(B21),1,"0000001",Holidays!A:A)+hour(B21+M$7-$B$1)/24+minute(B21)/1440),"") -> 46088.584 | N21: 46088.417 | O21: Done | P21: =IF(B21<>0,(if(O21="Pending",if($A$2>M21,$A$2-M21,0),if(N21>M21,N21-M21,0))),"") -> 0 | Q21: EMP0021 Tamanna Dewangan | R21: Requirements Clear | S21: =if(M21,if(and(hour(M21+S$7)>9.5,(hour(M21+S$7)<19.5)),M21+S$7,_xlfn.workday.intl(int(M21),1,"0000001",Holidays!A:A)+hour(M21+S$7-$B$1)/24+minute(M21)/1440),"") -> 46088.591 | T21: 46088.418 | U21: Done | V21: =IF(B21<>0,(if(U21="Pending",if($A$2>S21,$A$2-S21,0),if(T21>S21,T21-S21,0))),"") -> 0 | W21: =IF(B21<>"",Q21,"") -> EMP0021 Tamanna Dewangan | X21: =if(S21,if(and(hour(S21+X$7)>9.5,(hour(S21+X$7)<19.5)),S21+X$7,_xlfn.workday.intl(int(S21),1,"0000001",Holidays!A:A)+hour(S21+X$7-$B$1)/24+minute(S21)/1440),"") -> 46088.695 | Y21: 46088.418 | Z21: Done | AA21: =IF(B21<>0,(if(Z21="Pending",if($AD$1>X21,$AD$1-X21,0),if(Y21>X21,Y21-X21,0))),"") -> 0 | AB21: =IF(B21<>"",W21,"") -> EMP0021 Tamanna Dewangan | AC21: =if(X21,_xlfn.WORKDAY.INTL(X21,AC$7,"0000001",Holidays!A:A)+hour(X21)/24+MINUTE(X21)/1440,"") -> 46090.694 | AD21: 46088.482 | AE21: Done | AF21: =IF(B21<>0,(if(AD21="Pending",if($A$2>AC21,$A$2-AC21,0),if(AD21>AC21,AD21-AC21,0))),"") -> 0 | AG21: =IF(B21<>"",AB21,"") -> EMP0021 Tamanna Dewangan | AH21: =if(AC21,if(and(hour(AC21+AH$7)>9.5,(hour(AC21+AH$7)<19.5)),AC21+AH$7,_xlfn.workday.intl(int(AC21),1,"0000001",Holidays!A:A)+hour(AC21+AH$7-$B$1)/24+minute(AC21)/1440),"") -> 46090.736 | AI21: 46088.482 | AJ21: Done | AK21: =IF(B21<>0,(if(AJ21="Pending",if($A$2>AH21,$A$2-AH21,0),if(AI21>AH21,AI21-AH21,0))),"") -> 0 | AL21: =IF(B21<>"",AG21,"") -> EMP0021 Tamanna Dewangan | AN21: Click Here
A22: =if($B22<>"",A21+1,"") -> 4973 | B22: 46088.443 | C22: Marks Sheet NEP | D22: SMKV | E22: https://drive.google.com/open?id=1V0vddiHHf4B6GfLRctFj1SAMRM3L74vN | G22: Course wise | H22: Change in design | I22: Smart-Exam | J22: Rohit Singh | L22: Please implement the changes as per discussion | M22: =if(B22,if(and(hour(B22+M$7)>9.5,(hour(B22+M$7)<19.5)),B22+M$7,_xlfn.workday.intl(int(B22),1,"0000001",Holidays!A:A)+hour(B22+M$7-$B$1)/24+minute(B22)/1440),"") -> 46088.61 | N22: 46088.449 | O22: Done | P22: =IF(B22<>0,(if(O22="Pending",if($A$2>M22,$A$2-M22,0),if(N22>M22,N22-M22,0))),"") -> 0 | Q22: EMP0042 HULESHWAR KUMAR SAHU | R22: Requirements Clear | S22: =if(M22,if(and(hour(M22+S$7)>9.5,(hour(M22+S$7)<19.5)),M22+S$7,_xlfn.workday.intl(int(M22),1,"0000001",Holidays!A:A)+hour(M22+S$7-$B$1)/24+minute(M22)/1440),"") -> 46088.617 | T22: 46088.449 | U22: Done | V22: =IF(B22<>0,(if(U22="Pending",if($A$2>S22,$A$2-S22,0),if(T22>S22,T22-S22,0))),"") -> 0 | W22: =IF(B22<>"",Q22,"") -> EMP0042 HULESHWAR KUMAR SAHU | X22: =if(S22,if(and(hour(S22+X$7)>9.5,(hour(S22+X$7)<19.5)),S22+X$7,_xlfn.workday.intl(int(S22),1,"0000001",Holidays!A:A)+hour(S22+X$7-$B$1)/24+minute(S22)/1440),"") -> 46088.721 | Y22: 46088.449 | Z22: Done | AA22: =IF(B22<>0,(if(Z22="Pending",if($AD$1>X22,$AD$1-X22,0),if(Y22>X22,Y22-X22,0))),"") -> 0 | AB22: =IF(B22<>"",W22,"") -> EMP0042 HULESHWAR KUMAR SAHU | AC22: =if(X22,_xlfn.WORKDAY.INTL(X22,AC$7,"0000001",Holidays!A:A)+hour(X22)/24+MINUTE(X22)/1440,"") -> 46090.72 | AD22: 46090.623 | AE22: Done | AF22: =IF(B22<>0,(if(AD22="Pending",if($A$2>AC22,$A$2-AC22,0),if(AD22>AC22,AD22-AC22,0))),"") -> 0 | AG22: =IF(B22<>"",AB22,"") -> EMP0042 HULESHWAR KUMAR SAHU | AH22: =if(AC22,if(and(hour(AC22+AH$7)>9.5,(hour(AC22+AH$7)<19.5)),AC22+AH$7,_xlfn.workday.intl(int(AC22),1,"0000001",Holidays!A:A)+hour(AC22+AH$7-$B$1)/24+minute(AC22)/1440),"") -> 46090.762 | AI22: 46090.672 | AJ22: Done | AK22: =IF(B22<>0,(if(AJ22="Pending",if($A$2>AH22,$A$2-AH22,0),if(AI22>AH22,AI22-AH22,0))),"") -> 0 | AL22: =IF(B22<>"",AG22,"") -> EMP0042 HULESHWAR KUMAR SAHU | AN22: Click Here
A23: =if($B23<>"",A22+1,"") -> 4974 | B23: 46090.496 | C23: M.S.W 3RD SEM TR NO OF PAGES | D23: IGU | E23: https://drive.google.com/open?id=1ptziOTMmZrCYpXt5GYuL_CSDh5BVDjfd | F23: https://drive.google.com/open?id=1GhOv8mz381d4E3x_VLwIW5-p1t9lLxhc | G23: M.S.W 3RD SEM TR NO OF PAGES | H23: Change in logic | I23: Smart-Exam | J23: HARSHIT KUMAR | L23: DO THE CORRECTION AS PER ATTACHMENT | M23: =if(B23,if(and(hour(B23+M$7)>9.5,(hour(B23+M$7)<19.5)),B23+M$7,_xlfn.workday.intl(int(B23),1,"0000001",Holidays!A:A)+hour(B23+M$7-$B$1)/24+minute(B23)/1440),"") -> 46090.663 | N23: 46090.519 | O23: Done | P23: =IF(B23<>0,(if(O23="Pending",if($A$2>M23,$A$2-M23,0),if(N23>M23,N23-M23,0))),"") -> 0 | Q23: EMP0042 HULESHWAR KUMAR SAHU | R23: Requirements Clear | S23: =if(M23,if(and(hour(M23+S$7)>9.5,(hour(M23+S$7)<19.5)),M23+S$7,_xlfn.workday.intl(int(M23),1,"0000001",Holidays!A:A)+hour(M23+S$7-$B$1)/24+minute(M23)/1440),"") -> 46090.67 | T23: 46090.519 | U23: Done | V23: =IF(B23<>0,(if(U23="Pending",if($A$2>S23,$A$2-S23,0),if(T23>S23,T23-S23,0))),"") -> 0 | W23: =IF(B23<>"",Q23,"") -> EMP0042 HULESHWAR KUMAR SAHU | X23: =if(S23,if(and(hour(S23+X$7)>9.5,(hour(S23+X$7)<19.5)),S23+X$7,_xlfn.workday.intl(int(S23),1,"0000001",Holidays!A:A)+hour(S23+X$7-$B$1)/24+minute(S23)/1440),"") -> 46090.774 | Y23: 46090.672 | Z23: Done | AA23: =IF(B23<>0,(if(Z23="Pending",if($AD$1>X23,$AD$1-X23,0),if(Y23>X23,Y23-X23,0))),"") -> 0 | AB23: =IF(B23<>"",W23,"") -> EMP0042 HULESHWAR KUMAR SAHU | AC23: =if(X23,_xlfn.WORKDAY.INTL(X23,AC$7,"0000001",Holidays!A:A)+hour(X23)/24+MINUTE(X23)/1440,"") -> 46091.774 | AD23: 46091.772 | AE23: Done | AF23: =IF(B23<>0,(if(AD23="Pending",if($A$2>AC23,$A$2-AC23,0),if(AD23>AC23,AD23-AC23,0))),"") -> 0 | AG23: =IF(B23<>"",AB23,"") -> EMP0042 HULESHWAR KUMAR SAHU | AH23: =if(AC23,if(and(hour(AC23+AH$7)>9.5,(hour(AC23+AH$7)<19.5)),AC23+AH$7,_xlfn.workday.intl(int(AC23),1,"0000001",Holidays!A:A)+hour(AC23+AH$7-$B$1)/24+minute(AC23)/1440),"") -> 46091.815 | AI23: 46091.775 | AJ23: Done | AK23: =IF(B23<>0,(if(AJ23="Pending",if($A$2>AH23,$A$2-AH23,0),if(AI23>AH23,AI23-AH23,0))),"") -> 0 | AL23: =IF(B23<>"",AG23,"") -> EMP0042 HULESHWAR KUMAR SAHU | AN23: Click Here
A24: =if($B24<>"",A23+1,"") -> 4975 | B24: 46090.535 | C24: Gold Medel Certificate Gnsu | D24: GNSU | E24: https://drive.google.com/open?id=1aWiOoYam2GpEK8YnwoRT49EBkzqy_8eU | G24: Gold Medel Certificate Final Year ( Annual Exam(PG)) PG MD - Anaesthesiology ( ANSTH)_SE15 | H24: Report not downloading | I24: Smart-Exam | J24: DEEPAK | L24: KINDLY UPDATE THE FOURTH CONVOCATION | M24: =if(B24,if(and(hour(B24+M$7)>9.5,(hour(B24+M$7)<19.5)),B24+M$7,_xlfn.workday.intl(int(B24),1,"0000001",Holidays!A:A)+hour(B24+M$7-$B$1)/24+minute(B24)/1440),"") -> 46090.701 | N24: 46090.62 | O24: Done | P24: =IF(B24<>0,(if(O24="Pending",if($A$2>M24,$A$2-M24,0),if(N24>M24,N24-M24,0))),"") -> 0 | Q24: EMP0042 HULESHWAR KUMAR SAHU | R24: Requirements Clear | S24: =if(M24,if(and(hour(M24+S$7)>9.5,(hour(M24+S$7)<19.5)),M24+S$7,_xlfn.workday.intl(int(M24),1,"0000001",Holidays!A:A)+hour(M24+S$7-$B$1)/24+minute(M24)/1440),"") -> 46090.708 | T24: 46090.621 | U24: Done | V24: =IF(B24<>0,(if(U24="Pending",if($A$2>S24,$A$2-S24,0),if(T24>S24,T24-S24,0))),"") -> 0 | W24: =IF(B24<>"",Q24,"") -> EMP0042 HULESHWAR KUMAR SAHU | X24: =if(S24,if(and(hour(S24+X$7)>9.5,(hour(S24+X$7)<19.5)),S24+X$7,_xlfn.workday.intl(int(S24),1,"0000001",Holidays!A:A)+hour(S24+X$7-$B$1)/24+minute(S24)/1440),"") -> 46090.813 | Y24: 46090.672 | Z24: Done | AA24: =IF(B24<>0,(if(Z24="Pending",if($AD$1>X24,$AD$1-X24,0),if(Y24>X24,Y24-X24,0))),"") -> 0 | AB24: =IF(B24<>"",W24,"") -> EMP0042 HULESHWAR KUMAR SAHU | AC24: =if(X24,_xlfn.WORKDAY.INTL(X24,AC$7,"0000001",Holidays!A:A)+hour(X24)/24+MINUTE(X24)/1440,"") -> 46091.812 | AD24: 46091.54 | AE24: Done | AF24: =IF(B24<>0,(if(AD24="Pending",if($A$2>AC24,$A$2-AC24,0),if(AD24>AC24,AD24-AC24,0))),"") -> 0 | AG24: =IF(B24<>"",AB24,"") -> EMP0042 HULESHWAR KUMAR SAHU | AH24: =if(AC24,if(and(hour(AC24+AH$7)>9.5,(hour(AC24+AH$7)<19.5)),AC24+AH$7,_xlfn.workday.intl(int(AC24),1,"0000001",Holidays!A:A)+hour(AC24+AH$7-$B$1)/24+minute(AC24)/1440),"") -> 46092.438 | AI24: 46091.54 | AJ24: Done | AK24: =IF(B24<>0,(if(AJ24="Pending",if($A$2>AH24,$A$2-AH24,0),if(AI24>AH24,AI24-AH24,0))),"") -> 0 | AL24: =IF(B24<>"",AG24,"") -> EMP0042 HULESHWAR KUMAR SAHU | AN24: Click Here
A25: =if($B25<>"",A24+1,"") -> 4976 | B25: 46090.538 | C25: ADMIT CARD | D25: IGU | E25: https://drive.google.com/open?id=18KNmdhuUgubw11G2MCGG5NxlwpOAV5Hd | G25: Regarding for M.ed 1st Sem regular admit card not show in roll number | H25: Report not downloading, Change in logic | I25: Smart-Exam | J25: CHINTU SINGH | L25: Regarding for M.ed 1st Sem regular admit card not show in roll number | M25: =if(B25,if(and(hour(B25+M$7)>9.5,(hour(B25+M$7)<19.5)),B25+M$7,_xlfn.workday.intl(int(B25),1,"0000001",Holidays!A:A)+hour(B25+M$7-$B$1)/24+minute(B25)/1440),"") -> 46090.705 | N25: 46090.62 | O25: Done | P25: =IF(B25<>0,(if(O25="Pending",if($A$2>M25,$A$2-M25,0),if(N25>M25,N25-M25,0))),"") -> 0 | Q25: EMP0021 Tamanna Dewangan | R25: Requirements Clear | S25: =if(M25,if(and(hour(M25+S$7)>9.5,(hour(M25+S$7)<19.5)),M25+S$7,_xlfn.workday.intl(int(M25),1,"0000001",Holidays!A:A)+hour(M25+S$7-$B$1)/24+minute(M25)/1440),"") -> 46090.712 | T25: 46090.621 | U25: Done | V25: =IF(B25<>0,(if(U25="Pending",if($A$2>S25,$A$2-S25,0),if(T25>S25,T25-S25,0))),"") -> 0 | W25: =IF(B25<>"",Q25,"") -> EMP0021 Tamanna Dewangan | X25: =if(S25,if(and(hour(S25+X$7)>9.5,(hour(S25+X$7)<19.5)),S25+X$7,_xlfn.workday.intl(int(S25),1,"0000001",Holidays!A:A)+hour(S25+X$7-$B$1)/24+minute(S25)/1440),"") -> 46090.816 | Y25: 46090.625 | Z25: Done | AA25: =IF(B25<>0,(if(Z25="Pending",if($AD$1>X25,$AD$1-X25,0),if(Y25>X25,Y25-X25,0))),"") -> 0 | AB25: =IF(B25<>"",W25,"") -> EMP0021 Tamanna Dewangan | AC25: =if(X25,_xlfn.WORKDAY.INTL(X25,AC$7,"0000001",Holidays!A:A)+hour(X25)/24+MINUTE(X25)/1440,"") -> 46091.815 | AD25: 46090.625 | AE25: Done | AF25: =IF(B25<>0,(if(AD25="Pending",if($A$2>AC25,$A$2-AC25,0),if(AD25>AC25,AD25-AC25,0))),"") -> 0 | AG25: =IF(B25<>"",AB25,"") -> EMP0021 Tamanna Dewangan | AH25: =if(AC25,if(and(hour(AC25+AH$7)>9.5,(hour(AC25+AH$7)<19.5)),AC25+AH$7,_xlfn.workday.intl(int(AC25),1,"0000001",Holidays!A:A)+hour(AC25+AH$7-$B$1)/24+minute(AC25)/1440),"") -> 46092.44 | AI25: 46090.625 | AJ25: Done | AK25: =IF(B25<>0,(if(AJ25="Pending",if($A$2>AH25,$A$2-AH25,0),if(AI25>AH25,AI25-AH25,0))),"") -> 0 | AL25: =IF(B25<>"",AG25,"") -> EMP0021 Tamanna Dewangan | AN25: Click Here
A26: =if($B26<>"",A25+1,"") -> 4977 | B26: 46090.54 | C26: Enrolment/Exam form report | D26: SKS International University | E26: https://drive.google.com/open?id=149MzaH_Hqy0Kc49qyQ8_hDoFh1wv57hv | G26: Course | H26: Other changes | I26: Smart-Exam | J26: Rajesh Gupta | L26: Please add the one Colome Year/Semester in this format | M26: =if(B26,if(and(hour(B26+M$7)>9.5,(hour(B26+M$7)<19.5)),B26+M$7,_xlfn.workday.intl(int(B26),1,"0000001",Holidays!A:A)+hour(B26+M$7-$B$1)/24+minute(B26)/1440),"") -> 46090.707 | N26: 46090.55 | O26: Done | P26: =IF(B26<>0,(if(O26="Pending",if($A$2>M26,$A$2-M26,0),if(N26>M26,N26-M26,0))),"") -> 0 | Q26: EMP0237 Swarnendu Chakraborty | R26: Requirements Clear | S26: =if(M26,if(and(hour(M26+S$7)>9.5,(hour(M26+S$7)<19.5)),M26+S$7,_xlfn.workday.intl(int(M26),1,"0000001",Holidays!A:A)+hour(M26+S$7-$B$1)/24+minute(M26)/1440),"") -> 46090.714 | T26: 46090.55 | U26: Done | V26: =IF(B26<>0,(if(U26="Pending",if($A$2>S26,$A$2-S26,0),if(T26>S26,T26-S26,0))),"") -> 0 | W26: =IF(B26<>"",Q26,"") -> EMP0237 Swarnendu Chakraborty | X26: =if(S26,if(and(hour(S26+X$7)>9.5,(hour(S26+X$7)<19.5)),S26+X$7,_xlfn.workday.intl(int(S26),1,"0000001",Holidays!A:A)+hour(S26+X$7-$B$1)/24+minute(S26)/1440),"") -> 46090.818 | Y26: 46090.55 | Z26: Done | AA26: =IF(B26<>0,(if(Z26="Pending",if($AD$1>X26,$AD$1-X26,0),if(Y26>X26,Y26-X26,0))),"") -> 0 | AB26: =IF(B26<>"",W26,"") -> EMP0237 Swarnendu Chakraborty | AC26: =if(X26,_xlfn.WORKDAY.INTL(X26,AC$7,"0000001",Holidays!A:A)+hour(X26)/24+MINUTE(X26)/1440,"") -> 46091.818 | AD26: 46091.469 | AE26: Done | AF26: =IF(B26<>0,(if(AD26="Pending",if($A$2>AC26,$A$2-AC26,0),if(AD26>AC26,AD26-AC26,0))),"") -> 0 | AG26: =IF(B26<>"",AB26,"") -> EMP0237 Swarnendu Chakraborty | AH26: =if(AC26,if(and(hour(AC26+AH$7)>9.5,(hour(AC26+AH$7)<19.5)),AC26+AH$7,_xlfn.workday.intl(int(AC26),1,"0000001",Holidays!A:A)+hour(AC26+AH$7-$B$1)/24+minute(AC26)/1440),"") -> 46092.443 | AI26: 46091.469 | AJ26: Done | AK26: =IF(B26<>0,(if(AJ26="Pending",if($A$2>AH26,$A$2-AH26,0),if(AI26>AH26,AI26-AH26,0))),"") -> 0 | AL26: =IF(B26<>"",AG26,"") -> EMP0237 Swarnendu Chakraborty | AN26: Click Here
A27: =if($B27<>"",A26+1,"") -> 4978 | B27: 46090.576 | C27: MULTIPLE REPORT | D27: SGBAU | E27: https://drive.google.com/open?id=1FHnmm9S1-hSTFSC3RsuK_6ONkwRAOhP5 | G27: MHRD TR | H27: Other changes | I27: Smart-Exam | J27: KAMINI THAKUR | L27: TR RESULT HOSTING COLLEGEWISE ME TH MHRD KA FILE HONA | M27: =if(B27,if(and(hour(B27+M$7)>9.5,(hour(B27+M$7)<19.5)),B27+M$7,_xlfn.workday.intl(int(B27),1,"0000001",Holidays!A:A)+hour(B27+M$7-$B$1)/24+minute(B27)/1440),"") -> 46090.743 | N27: 46090.62 | O27: Done | P27: =IF(B27<>0,(if(O27="Pending",if($A$2>M27,$A$2-M27,0),if(N27>M27,N27-M27,0))),"") -> 0 | Q27: EMP0042 HULESHWAR KUMAR SAHU | R27: Requirements Clear | S27: =if(M27,if(and(hour(M27+S$7)>9.5,(hour(M27+S$7)<19.5)),M27+S$7,_xlfn.workday.intl(int(M27),1,"0000001",Holidays!A:A)+hour(M27+S$7-$B$1)/24+minute(M27)/1440),"") -> 46090.75 | T27: 46090.773 | U27: Done | V27: =IF(B27<>0,(if(U27="Pending",if($A$2>S27,$A$2-S27,0),if(T27>S27,T27-S27,0))),"") -> 0.023352025 | W27: =IF(B27<>"",Q27,"") -> EMP0042 HULESHWAR KUMAR SAHU | X27: =if(S27,if(and(hour(S27+X$7)>9.5,(hour(S27+X$7)<19.5)),S27+X$7,_xlfn.workday.intl(int(S27),1,"0000001",Holidays!A:A)+hour(S27+X$7-$B$1)/24+minute(S27)/1440),"") -> 46091.458 | Y27: 46090.773 | Z27: Done | AA27: =IF(B27<>0,(if(Z27="Pending",if($AD$1>X27,$AD$1-X27,0),if(Y27>X27,Y27-X27,0))),"") -> 0 | AB27: =IF(B27<>"",W27,"") -> EMP0042 HULESHWAR KUMAR SAHU | AC27: =if(X27,_xlfn.WORKDAY.INTL(X27,AC$7,"0000001",Holidays!A:A)+hour(X27)/24+MINUTE(X27)/1440,"") -> 46092.458 | AD27: 46091.54 | AE27: Done | AF27: =IF(B27<>0,(if(AD27="Pending",if($A$2>AC27,$A$2-AC27,0),if(AD27>AC27,AD27-AC27,0))),"") -> 0 | AG27: =IF(B27<>"",AB27,"") -> EMP0042 HULESHWAR KUMAR SAHU | AH27: =if(AC27,if(and(hour(AC27+AH$7)>9.5,(hour(AC27+AH$7)<19.5)),AC27+AH$7,_xlfn.workday.intl(int(AC27),1,"0000001",Holidays!A:A)+hour(AC27+AH$7-$B$1)/24+minute(AC27)/1440),"") -> 46092.499 | AI27: 46091.54 | AJ27: Done | AK27: =IF(B27<>0,(if(AJ27="Pending",if($A$2>AH27,$A$2-AH27,0),if(AI27>AH27,AI27-AH27,0))),"") -> 0 | AL27: =IF(B27<>"",AG27,"") -> EMP0042 HULESHWAR KUMAR SAHU | AN27: Click Here
A28: =if($B28<>"",A27+1,"") -> 4979 | B28: 46090.595 | C28: Degree certificate correction | D28: MGU | E28: https://drive.google.com/open?id=1qNvVBFPAHJiUBsWL1nv9u2wF3iJvNQFW | G28: FINAL YEAR | H28: Change in logic | I28: Smart-Exam | J28: Tusar Chhatui | L28: Degree certificate correction | M28: =if(B28,if(and(hour(B28+M$7)>9.5,(hour(B28+M$7)<19.5)),B28+M$7,_xlfn.workday.intl(int(B28),1,"0000001",Holidays!A:A)+hour(B28+M$7-$B$1)/24+minute(B28)/1440),"")+1 -> 46091.762 | N28: 46091.468 | O28: Done | P28: =IF(B28<>0,(if(O28="Pending",if($A$2>M28,$A$2-M28,0),if(N28>M28,N28-M28,0))),"") -> 0 | Q28: EMP0042 HULESHWAR KUMAR SAHU | R28: Requirements Clear | S28: =if(M28,if(and(hour(M28+S$7)>9.5,(hour(M28+S$7)<19.5)),M28+S$7,_xlfn.workday.intl(int(M28),1,"0000001",Holidays!A:A)+hour(M28+S$7-$B$1)/24+minute(M28)/1440),"") -> 46091.768 | T28: 46091.468 | U28: Done | V28: =IF(B28<>0,(if(U28="Pending",if($A$2>S28,$A$2-S28,0),if(T28>S28,T28-S28,0))),"") -> 0 | W28: =IF(B28<>"",Q28,"") -> EMP0042 HULESHWAR KUMAR SAHU | X28: 46091.476 | Y28: 46091.469 | Z28: Done | AA28: =IF(B28<>0,(if(Z28="Pending",if($AD$1>X28,$AD$1-X28,0),if(Y28>X28,Y28-X28,0))),"") -> 0 | AB28: =IF(B28<>"",W28,"") -> EMP0042 HULESHWAR KUMAR SAHU | AC28: =if(X28,_xlfn.WORKDAY.INTL(X28,AC$7,"0000001",Holidays!A:A)+hour(X28)/24+MINUTE(X28)/1440,"") -> 46092.476 | AD28: 46091.469 | AE28: Done | AF28: =IF(B28<>0,(if(AD28="Pending",if($A$2>AC28,$A$2-AC28,0),if(AD28>AC28,AD28-AC28,0))),"") -> 0 | AG28: =IF(B28<>"",AB28,"") -> EMP0042 HULESHWAR KUMAR SAHU | AH28: =if(AC28,if(and(hour(AC28+AH$7)>9.5,(hour(AC28+AH$7)<19.5)),AC28+AH$7,_xlfn.workday.intl(int(AC28),1,"0000001",Holidays!A:A)+hour(AC28+AH$7-$B$1)/24+minute(AC28)/1440),"") -> 46092.518 | AI28: 46091.469 | AJ28: Done | AK28: =IF(B28<>0,(if(AJ28="Pending",if($A$2>AH28,$A$2-AH28,0),if(AI28>AH28,AI28-AH28,0))),"") -> 0 | AL28: =IF(B28<>"",AG28,"") -> EMP0042 HULESHWAR KUMAR SAHU | AN28: Click Here
